Traceback (most recent call last):
  File "c:\users\natsciteaching\appdata\local\programs\python\python37\lib\site-packages\jupyter_cache\executors\utils.py", line 56, in single_nb_execution
    record_timing=False,
  File "c:\users\natsciteaching\appdata\local\programs\python\python37\lib\site-packages\nbclient\client.py", line 1204, in execute
    return NotebookClient(nb=nb, resources=resources, km=km, **kwargs).execute()
  File "c:\users\natsciteaching\appdata\local\programs\python\python37\lib\site-packages\nbclient\util.py", line 84, in wrapped
    return just_run(coro(*args, **kwargs))
  File "c:\users\natsciteaching\appdata\local\programs\python\python37\lib\site-packages\nbclient\util.py", line 62, in just_run
    return loop.run_until_complete(coro)
  File "c:\users\natsciteaching\appdata\local\programs\python\python37\lib\asyncio\base_events.py", line 587, in run_until_complete
    return future.result()
  File "c:\users\natsciteaching\appdata\local\programs\python\python37\lib\site-packages\nbclient\client.py", line 664, in async_execute
    cell, index, execution_count=self.code_cells_executed + 1
  File "c:\users\natsciteaching\appdata\local\programs\python\python37\lib\site-packages\nbclient\client.py", line 965, in async_execute_cell
    await self._check_raise_for_error(cell, cell_index, exec_reply)
  File "c:\users\natsciteaching\appdata\local\programs\python\python37\lib\site-packages\nbclient\client.py", line 862, in _check_raise_for_error
    raise CellExecutionError.from_cell_and_msg(cell, exec_reply_content)
nbclient.exceptions.CellExecutionError: An error occurred while executing the following cell:
------------------
import plotly.graph_objs as go
import plotly

#the start and end point for each line
#pairs = [(0,6), (1,7)]


p1 = [1, -2, 3]
v1 = [1, -1, 2]

p2 = [4, 2, 4]
v2 = [3, 4, 1]

a = p1 + -2*np.array(v1)
b = p1 + 2*np.array(v1)

c = p2 + -2*np.array(v2)
d = p2 + 2*np.array(v2)

x_lines = [a[0], b[0], None, c[0], d[0]]
y_lines = [a[1], b[1], None, c[1], d[1]]
z_lines = [a[2], b[2], None, c[2], d[2]]

trace2 = go.Scatter3d(
    x=x_lines,
    y=y_lines,
    z=z_lines,
    mode='lines',
    name='lines'
)



fig = go.Figure(data=[trace2])
plotly.offline.iplot(fig, filename='simple-3d-scatter')
------------------

[1;31m---------------------------------------------------------------------------[0m
[1;31mNameError[0m                                 Traceback (most recent call last)
[1;32m~\AppData\Local\Temp\ipykernel_13712\2943108528.py[0m in [0;36m<module>[1;34m[0m
[0;32m     12[0m [0mv2[0m [1;33m=[0m [1;33m[[0m[1;36m3[0m[1;33m,[0m [1;36m4[0m[1;33m,[0m [1;36m1[0m[1;33m][0m[1;33m[0m[1;33m[0m[0m
[0;32m     13[0m [1;33m[0m[0m
[1;32m---> 14[1;33m [0ma[0m [1;33m=[0m [0mp1[0m [1;33m+[0m [1;33m-[0m[1;36m2[0m[1;33m*[0m[0mnp[0m[1;33m.[0m[0marray[0m[1;33m([0m[0mv1[0m[1;33m)[0m[1;33m[0m[1;33m[0m[0m
[0m[0;32m     15[0m [0mb[0m [1;33m=[0m [0mp1[0m [1;33m+[0m [1;36m2[0m[1;33m*[0m[0mnp[0m[1;33m.[0m[0marray[0m[1;33m([0m[0mv1[0m[1;33m)[0m[1;33m[0m[1;33m[0m[0m
[0;32m     16[0m [1;33m[0m[0m

[1;31mNameError[0m: name 'np' is not defined
NameError: name 'np' is not defined

